Traceback (most recent call last):
  File "C:\Users\YangShuhao\AppData\Local\Temp\ipykernel_7472\4214086022.py", line 3, in <cell line: 2>
    raise Exception('This is the error message.')
Exception: This is the error message.
